const x = 2
try {
    x = 2
} catch(err) {
    console.log(`ERRO: ${err}`)
}